Workbook

Sheet Roadmap
A1: Roadmap — Gesto (Faro Sistemas)
A2: SaaS de gestión comercial multi-tenant · Actualizado 2026-06-22 · Editá la columna Estado y la fecha al cerrar cada tarea
A4: ID | B4: Categoría | C4: Tarea | D4: Prioridad | E4: Estado | F4: Notas | G4: Actualizado
A5: 1 | B5: Infraestructura | C5: Stack Next.js 16 App Router + TypeScript strict + Turbopack | D5: — | E5: Hecho | G5: 2026-06-22
A6: 2 | B6: Infraestructura | C6: Tailwind v4 + shadcn/ui + Design System Brasas | D6: — | E6: Hecho | G6: 2026-06-22
A7: 3 | B7: Infraestructura | C7: Drizzle ORM + Supabase Postgres | D7: — | E7: Hecho | G7: 2026-06-22
A8: 4 | B8: Infraestructura | C8: Supabase Auth SSR + middleware de sesión | D8: — | E8: Hecho | G8: 2026-06-22
A9: 5 | B9: Infraestructura | C9: Framer Motion + command palette (cmdk) | D9: — | E9: Hecho | G9: 2026-06-22
A10: 6 | B10: Base de datos | C10: Schema multi-tenant (tenants, users, productos, clientes, ventas, pagos, CC) | D10: — | E10: Hecho | F10: 10 tablas (+ presupuestos) | G10: 2026-06-22
A11: 7 | B11: Base de datos | C11: Migraciones aplicadas en Supabase | D11: — | E11: Hecho | G11: 2026-06-22
A12: 8 | B12: Base de datos | C12: RLS multi-tenant (16 políticas, script defensivo) | D12: — | E12: Hecho | F12: byTenant() + RLS como red de seguridad | G12: 2026-06-22
A13: 9 | B13: Auth | C13: Login / Signup / Onboarding (crear tenant) | D13: — | E13: Hecho | G13: 2026-06-22
A14: 10 | B14: Auth | C14: Recuperar contraseña (forgot + reset) | D14: — | E14: Hecho | G14: 2026-06-22
A15: 11 | B15: Auth | C15: Auth callback PKCE + token_hash | D15: — | E15: Hecho | G15: 2026-06-22
A16: 12 | B16: Productos | C16: CRUD productos (stock kg/unidad, precios may/min) | D16: — | E16: Hecho | F16: Title Case, inputs vacíos no 0 | G16: 2026-06-22
A17: 13 | B17: Productos | C17: Carga rápida (scan → nombre → precio → siguiente) | D17: — | E17: Hecho | F17: /productos/carga-rapida | G17: 2026-06-22
A18: 14 | B18: Productos | C18: Importación CSV con preview y validación | D18: — | E18: Hecho | F18: lotes de 100, crea categorías | G18: 2026-06-22
A19: 15 | B19: Productos | C19: Categorías (CRUD + filtro en lista y POS) | D19: — | E19: Hecho | G19: 2026-06-22
A20: 16 | B20: Productos | C20: Grupos de variantes + sugerencia asistida | D20: — | E20: Hecho | G20: 2026-06-22
A21: 17 | B21: Productos | C21: Código PLU (plan balanza) | D21: — | E21: Hecho | G21: 2026-06-22
A22: 18 | B22: Productos | C22: Precios vivos (anti-inflación: margen + actualización masiva) | D22: Alta | E22: En progreso | F22: Falta QA en vivo los 3 planes; ver docs/context/precios.md | G22: 2026-06-22
A23: 19 | B23: Productos | C23: Alertas de stock bajo (banner/email cuando stock ≤ mínimo) | D23: Media | E23: Pendiente | F23: El campo existe, no dispara nada | G23: 2026-06-22
A24: 20 | B24: Productos | C24: Precios especiales por cliente | D24: Media | E24: Pendiente | F24: Mayoristas con acuerdos puntuales | G24: 2026-06-22
A25: 21 | B25: Clientes | C25: CRUD clientes + ficha con saldo CC | D25: — | E25: Hecho | F25: tipo, condición IVA, descuento | G25: 2026-06-22
A26: 22 | B26: Ventas / POS | C26: POS unificado mayorista + minorista (carrito Zustand) | D26: — | E26: Hecho | F26: split-screen | G26: 2026-06-22
A27: 23 | B27: Ventas / POS | C27: Scanner de código de barras (ZXing, cámara real) | D27: — | E27: Hecho | G27: 2026-06-22
A28: 24 | B28: Ventas / POS | C28: Métodos de pago (efectivo, transf, tarjeta, MP, cuenta corriente) | D28: — | E28: Hecho | G28: 2026-06-22
A29: 25 | B29: Ventas / POS | C29: Ticket 80mm + Remito A4 PDF (compartir / descargar) | D29: — | E29: Hecho | F29: @react-pdf/renderer | G29: 2026-06-22
A30: 26 | B30: Ventas / POS | C30: Atajos de teclado (F2 cobrar, Esc, Supr) | D30: — | E30: Hecho | G30: 2026-06-22
A31: 27 | B31: Ventas / POS | C31: Historial + detalle de venta (filtro por período) | D31: — | E31: Hecho | G31: 2026-06-22
A32: 28 | B32: Ventas / POS | C32: Descuentos en POS (% o $ por total) | D32: Media | E32: Pendiente | F32: Muy pedido en kioscos/carnicerías | G32: 2026-06-22
A33: 29 | B33: Ventas / POS | C33: Devoluciones / notas de crédito (reversar venta + ajuste stock) | D33: Media | E33: Pendiente | F33: Reversión de CC ya está hecha | G33: 2026-06-22
A34: 30 | B34: Ventas / POS | C34: Lector de códigos USB en POS desktop (Enter agrega el producto escaneado) | D34: — | E34: Hecho | F34: Minorista + mayorista; el lector tipo supermercado escribe el código y Enter lo suma al carrito | G34: 2026-06-22
A35: 31 | B35: Cuenta Corriente | C35: Movimientos + registrar pago + saldo en tiempo real | D35: — | E35: Hecho | F35: registrarPago atómico FOR UPDATE | G35: 2026-06-22
A36: 32 | B36: Cuenta Corriente | C36: Reversión de movimientos (transacción atómica) | D36: — | E36: Hecho | F36: motivo obligatorio | G36: 2026-06-22
A37: 33 | B37: Reportes | C37: KPIs por período + ranking top productos + métodos de pago | D37: — | E37: Hecho | F37: ventana de tiempo unificada | G37: 2026-06-22
A38: 34 | B38: Reportes | C38: Exportar a CSV | D38: — | E38: Hecho | G38: 2026-06-22
A39: 35 | B39: Presupuestos | C39: CRUD + PDF + estados + numeración atómica | D39: — | E39: Hecho | F39: db.transaction | G39: 2026-06-22
A40: 36 | B40: Presupuestos | C40: Plantillas de servicios (guardar/listar/usar) | D40: — | E40: Hecho | G40: 2026-06-22
A41: 37 | B41: Proveedores / Pedidos | C41: CRUD proveedores (markup, selector de país) | D41: — | E41: Hecho | G41: 2026-06-22
...

Sheet Resumen
A1: Resumen del Roadmap
A3: Estado | B3: Cantidad | C3: % del total
A4: Hecho | B4: =COUNTIF(Roadmap!$E$5:$E$101,A4) | C4: =IFERROR(B4/$B$7,0)
A5: En progreso | B5: =COUNTIF(Roadmap!$E$5:$E$101,A5) | C5: =IFERROR(B5/$B$7,0)
A6: Pendiente | B6: =COUNTIF(Roadmap!$E$5:$E$101,A6) | C6: =IFERROR(B6/$B$7,0)
A7: TOTAL | B7: =COUNTA(Roadmap!$E$5:$E$101)
A10: Categoría | B10: Hecho | C10: Pendiente/En curso
A11: Infraestructura | B11: =COUNTIFS(Roadmap!$B$5:$B$101,A11,Roadmap!$E$5:$E$101,"Hecho") | C11: =COUNTIFS(Roadmap!$B$5:$B$101,A11)-B11
A12: Base de datos | B12: =COUNTIFS(Roadmap!$B$5:$B$101,A12,Roadmap!$E$5:$E$101,"Hecho") | C12: =COUNTIFS(Roadmap!$B$5:$B$101,A12)-B12
A13: Auth | B13: =COUNTIFS(Roadmap!$B$5:$B$101,A13,Roadmap!$E$5:$E$101,"Hecho") | C13: =COUNTIFS(Roadmap!$B$5:$B$101,A13)-B13
A14: Productos | B14: =COUNTIFS(Roadmap!$B$5:$B$101,A14,Roadmap!$E$5:$E$101,"Hecho") | C14: =COUNTIFS(Roadmap!$B$5:$B$101,A14)-B14
A15: Clientes | B15: =COUNTIFS(Roadmap!$B$5:$B$101,A15,Roadmap!$E$5:$E$101,"Hecho") | C15: =COUNTIFS(Roadmap!$B$5:$B$101,A15)-B15
A16: Ventas / POS | B16: =COUNTIFS(Roadmap!$B$5:$B$101,A16,Roadmap!$E$5:$E$101,"Hecho") | C16: =COUNTIFS(Roadmap!$B$5:$B$101,A16)-B16
A17: Cuenta Corriente | B17: =COUNTIFS(Roadmap!$B$5:$B$101,A17,Roadmap!$E$5:$E$101,"Hecho") | C17: =COUNTIFS(Roadmap!$B$5:$B$101,A17)-B17
A18: Reportes | B18: =COUNTIFS(Roadmap!$B$5:$B$101,A18,Roadmap!$E$5:$E$101,"Hecho") | C18: =COUNTIFS(Roadmap!$B$5:$B$101,A18)-B18
A19: Presupuestos | B19: =COUNTIFS(Roadmap!$B$5:$B$101,A19,Roadmap!$E$5:$E$101,"Hecho") | C19: =COUNTIFS(Roadmap!$B$5:$B$101,A19)-B19
A20: Proveedores / Pedidos | B20: =COUNTIFS(Roadmap!$B$5:$B$101,A20,Roadmap!$E$5:$E$101,"Hecho") | C20: =COUNTIFS(Roadmap!$B$5:$B$101,A20)-B20
A21: Configuración / Equipo | B21: =COUNTIFS(Roadmap!$B$5:$B$101,A21,Roadmap!$E$5:$E$101,"Hecho") | C21: =COUNTIFS(Roadmap!$B$5:$B$101,A21)-B21
A22: UX / Diseño | B22: =COUNTIFS(Roadmap!$B$5:$B$101,A22,Roadmap!$E$5:$E$101,"Hecho") | C22: =COUNTIFS(Roadmap!$B$5:$B$101,A22)-B22
... A31: Marketing / Conversión | B31: =COUNTIFS(Roadmap!$B$5:$B$101,A31,Roadmap!$E$5:$E$101,"Hecho") | C31: =COUNTIFS(Roadmap!$B$5:$B$101,A31)-B31
